Traceback (most recent call last):
  File "C:\Users\zschende\Miniconda3\envs\atbd\Lib\site-packages\jupyter_cache\executors\utils.py", line 58, in single_nb_execution
    executenb(
  File "C:\Users\zschende\Miniconda3\envs\atbd\Lib\site-packages\nbclient\client.py", line 1204, in execute
    return NotebookClient(nb=nb, resources=resources, km=km, **kwargs).execute()
           ^^^^^^^^^^^^^^^^^^^^^^^^^^^^^^^^^^^^^^^^^^^^^^^^^^^^^^^^^^^^^^^^^^^^^
  File "C:\Users\zschende\Miniconda3\envs\atbd\Lib\site-packages\nbclient\util.py", line 84, in wrapped
    return just_run(coro(*args, **kwargs))
           ^^^^^^^^^^^^^^^^^^^^^^^^^^^^^^^
  File "C:\Users\zschende\Miniconda3\envs\atbd\Lib\site-packages\nbclient\util.py", line 62, in just_run
    return loop.run_until_complete(coro)
           ^^^^^^^^^^^^^^^^^^^^^^^^^^^^^
  File "C:\Users\zschende\Miniconda3\envs\atbd\Lib\asyncio\base_events.py", line 650, in run_until_complete
    return future.result()
           ^^^^^^^^^^^^^^^
  File "C:\Users\zschende\Miniconda3\envs\atbd\Lib\contextlib.py", line 222, in __aexit__
    await self.gen.athrow(typ, value, traceback)
  File "C:\Users\zschende\Miniconda3\envs\atbd\Lib\site-packages\nbclient\client.py", line 608, in async_setup_kernel
    yield
  File "C:\Users\zschende\Miniconda3\envs\atbd\Lib\site-packages\nbclient\client.py", line 663, in async_execute
    await self.async_execute_cell(
  File "C:\Users\zschende\Miniconda3\envs\atbd\Lib\site-packages\nbclient\client.py", line 965, in async_execute_cell
    await self._check_raise_for_error(cell, cell_index, exec_reply)
  File "C:\Users\zschende\Miniconda3\envs\atbd\Lib\site-packages\nbclient\client.py", line 862, in _check_raise_for_error
    raise CellExecutionError.from_cell_and_msg(cell, exec_reply_content)
nbclient.exceptions.CellExecutionError: An error occurred while executing the following cell:
------------------
import os
import xarray as xr
import numpy as np
import pandas as pd
import pyresample as pr
from scipy import spatial
import matplotlib.image
from matplotlib import pyplot as plt
from matplotlib import colors
import datetime as dt
import cartopy
from cartopy import crs as ccrs, feature as cfeature
------------------

[1;31m----------------------------------------------------------------------[0m
[1;31mModuleNotFoundError[0m                  Traceback (most recent call last)
Cell [1;32mIn[1], line 5[0m
[0;32m      3[0m [38;5;28;01mimport[39;00m [38;5;21;01mnumpy[39;00m [38;5;28;01mas[39;00m [38;5;21;01mnp[39;00m
[0;32m      4[0m [38;5;28;01mimport[39;00m [38;5;21;01mpandas[39;00m [38;5;28;01mas[39;00m [38;5;21;01mpd[39;00m
[1;32m----> 5[0m [38;5;28;01mimport[39;00m [38;5;21;01mpyresample[39;00m [38;5;28;01mas[39;00m [38;5;21;01mpr[39;00m
[0;32m      6[0m [38;5;28;01mfrom[39;00m [38;5;21;01mscipy[39;00m [38;5;28;01mimport[39;00m spatial
[0;32m      7[0m [38;5;28;01mimport[39;00m [38;5;21;01mmatplotlib[39;00m[38;5;21;01m.[39;00m[38;5;21;01mimage[39;00m

[1;31mModuleNotFoundError[0m: No module named 'pyresample'
ModuleNotFoundError: No module named 'pyresample'

