Traceback (most recent call last):
  File "C:\Users\zschende\Miniconda3\lib\site-packages\jupyter_cache\executors\utils.py", line 58, in single_nb_execution
    executenb(
  File "C:\Users\zschende\Miniconda3\lib\site-packages\nbclient\client.py", line 1204, in execute
    return NotebookClient(nb=nb, resources=resources, km=km, **kwargs).execute()
  File "C:\Users\zschende\Miniconda3\lib\site-packages\nbclient\util.py", line 84, in wrapped
    return just_run(coro(*args, **kwargs))
  File "C:\Users\zschende\Miniconda3\lib\site-packages\nbclient\util.py", line 62, in just_run
    return loop.run_until_complete(coro)
  File "C:\Users\zschende\Miniconda3\lib\asyncio\base_events.py", line 647, in run_until_complete
    return future.result()
  File "C:\Users\zschende\Miniconda3\lib\site-packages\nbclient\client.py", line 663, in async_execute
    await self.async_execute_cell(
  File "C:\Users\zschende\Miniconda3\lib\site-packages\nbclient\client.py", line 965, in async_execute_cell
    await self._check_raise_for_error(cell, cell_index, exec_reply)
  File "C:\Users\zschende\Miniconda3\lib\site-packages\nbclient\client.py", line 862, in _check_raise_for_error
    raise CellExecutionError.from_cell_and_msg(cell, exec_reply_content)
nbclient.exceptions.CellExecutionError: An error occurred while executing the following cell:
------------------
#l1x_geo = '../data/W_PT-DME-Lisbon-SAT-CIMR-1X@KA_C_DME_20230417T105425_LD_20280110T114800_20280110T115700_TN.nc'
l1x_geo = 'C:/Users/zschende/OneDrive - Ilmatieteen laitos/Files/CIMR Devalgo/Data/L1C Files/Geometric/W_PT-DME-Lisbon-SAT-CIMR-1X@KA_C_DME_20230417T105425_LD_20280110T114800_20280110T115700_TN.nc'
FWD_geolocation_geo = xr.open_dataset(l1x_geo, group='FWD_geolocation')
BCK_geolocation_geo = xr.open_dataset(l1x_geo, group='BCK_geolocation')
data_fwd_geo = dict()
data_bck_geo = dict()

#l1x_rad = '../data/W_PT-DME-Lisbon-SAT-CIMR-1X@KA_C_DME_20230420T103323_LD_20280110T114800_20280110T115700_TN.nc'
l1x_geo = 'C:/Users/zschende/OneDrive - Ilmatieteen laitos/Files/CIMR Devalgo/Data/L1C Files/Radiometric/W_PT-DME-Lisbon-SAT-CIMR-1X@KA_C_DME_20230420T103323_LD_20280110T114800_20280110T115700_TN.nc'
FWD_geolocation_rad = xr.open_dataset(l1x_rad, group='FWD_geolocation')
BCK_geolocation_rad = xr.open_dataset(l1x_rad, group='BCK_geolocation')
data_fwd_rad = dict()
data_bck_rad = dict()

bands = ('L', 'C', 'X', 'KU', 'KA')
for gr in bands:
    data_fwd_geo[gr] = xr.open_dataset(l1x_geo, group='FWD_' + gr + '_BAND')
    data_bck_geo[gr] = xr.open_dataset(l1x_geo, group='BCK_' + gr + '_BAND')
    data_fwd_rad[gr] = xr.open_dataset(l1x_rad, group='FWD_' + gr + '_BAND')
    data_bck_rad[gr] = xr.open_dataset(l1x_rad, group='BCK_' + gr + '_BAND')
------------------

[1;31m---------------------------------------------------------------------------[0m
[1;31mNameError[0m                                 Traceback (most recent call last)
Input [1;32mIn [2][0m, in [0;36m<cell line: 10>[1;34m()[0m
[0;32m      8[0m [38;5;66;03m#l1x_rad = '../data/W_PT-DME-Lisbon-SAT-CIMR-1X@KA_C_DME_20230420T103323_LD_20280110T114800_20280110T115700_TN.nc'[39;00m
[0;32m      9[0m l1x_geo [38;5;241m=[39m [38;5;124m'[39m[38;5;124mC:/Users/zschende/OneDrive - Ilmatieteen laitos/Files/CIMR Devalgo/Data/L1C Files/Radiometric/W_PT-DME-Lisbon-SAT-CIMR-1X@KA_C_DME_20230420T103323_LD_20280110T114800_20280110T115700_TN.nc[39m[38;5;124m'[39m
[1;32m---> 10[0m FWD_geolocation_rad [38;5;241m=[39m xr[38;5;241m.[39mopen_dataset([43ml1x_rad[49m, group[38;5;241m=[39m[38;5;124m'[39m[38;5;124mFWD_geolocation[39m[38;5;124m'[39m)
[0;32m     11[0m BCK_geolocation_rad [38;5;241m=[39m xr[38;5;241m.[39mopen_dataset(l1x_rad, group[38;5;241m=[39m[38;5;124m'[39m[38;5;124mBCK_geolocation[39m[38;5;124m'[39m)
[0;32m     12[0m data_fwd_rad [38;5;241m=[39m [38;5;28mdict[39m()

[1;31mNameError[0m: name 'l1x_rad' is not defined
NameError: name 'l1x_rad' is not defined

